<?xml version="1.0"?>
<robot name="three_axis_robot">

  <!-- base -->
  <link name="base_link">
    <!-- <visual>
      <origin xyz="0 0 0" rpy="1.5708 0 0"/>
      <geometry>
        <mesh filename="meshes/base_link_modified.stl" scale="0.001 0.001 0.001"/>
      </geometry>

    <material name="grey_material">
      <color rgba="0.3 0.3 0.3 1.0"/>
    </material>
    </visual> -->
  </link>

  <!-- joint1: base_link -> link1 -->
  <joint name="joint1" type="revolute">
    <parent link="base_link"/>
    <child link="link1"/>
    <origin xyz="0 0 0.065" rpy="1.5708 0 0"/>
    <axis xyz="0 1 0"/>
    <limit lower="-2.0944" upper="2.4435" effort="1" velocity="3.49"/>
  </joint>

  <link name="link1">
    <!-- <visual>
      <geometry>
        <mesh filename="meshes/Link1_modified.stl" scale="0.001 0.001 0.001"/>
      </geometry>

    <material name="dark_grey_material">
      <color rgba="0.1 0.1 0.1 1.0"/>
    </material>
    </visual> -->
  </link>

  <!-- joint2: link1 -> link2 -->
  <joint name="joint2" type="revolute">
    <parent link="link1"/>
    <child link="link2"/>
    <origin xyz="0.045 0.08 0" rpy="0 0 0"/>
    <axis xyz="0 0 1"/>
    <limit lower="-0.5759" upper="0.9948" effort="1" velocity="3.49"/>
  </joint>

  <link name="link2">
    <visual>
      <geometry>
        <mesh filename="meshes/Link2_modified.stl" scale="0.001 0.001 0.001"/>
      </geometry>
    <material name="Orange">
      <color rgba="1.0 0.6 0.0 1.0"/>
    </material>
    </visual>
  </link>

  <!-- joint3: link2 -> link3 -->
  <joint name="joint3" type="revolute">
    <parent link="link2"/>
    <child link="link3"/>
    <origin xyz="0 0.13 0.008" rpy="1.5708 3.1416 0"/>
    <axis xyz="0 1 0"/>
    <limit lower="-0.2443" upper="0.9948" effort="1" velocity="3.49"/>
  </joint>

  <link name="link3">
    <visual>
      <origin xyz="-0.15 0 0" rpy="0 0 0"/>
      <geometry>
        <mesh filename="meshes/Link3_modified.stl" scale="0.001 0.001 0.001"/>
      </geometry>
    <material name="Orange">
      <color rgba="1.0 0.6 0.0 1.0"/>
    </material>
    </visual>
  </link>

  <!-- fixed joint: link3 - link4 -->
  <joint name="joint4" type="fixed">
    <parent link="link3"/>
    <child link="link4"/>
    <origin xyz="-0.15 0.008 0" rpy="-1.5708 0 -1.5708"/>
  </joint>

  <link name="link4">
    <!-- <visual>
      <geometry>
        <mesh filename="meshes/Link4_modified.stl" scale="0.00001 0.00001 0.00001"/>
      </geometry>
    </visual> -->
  </link>
<link name="link2_mimic">

  <origin xyz="0 0 0" rpy="1.5708 0 0"/>
  <!-- <visual> -->
    <!-- <geometry> -->
    <!-- <box size="0.001 0.001 0.001"/> -->
      <!-- <mesh filename="/meshes/0001-01 L130_modified.stl" scale="0.001 0.001 0.001"/> -->
    <!-- </geometry> -->
  <!-- </visual> -->
</link>

<!-- mimic joint -->
<joint name="joint2_mimic" type="revolute">
  <parent link="link3"/>
  <child link="link2_mimic"/>
  <origin xyz="0.04 0 0" rpy=" 0 0 0"/> 
  <axis xyz="0 0 1"/>
  <mimic joint="joint3" multiplier="1.0" offset="0.0"/>
</joint>


</robot>
